[2025-04-25 22:57:29,170 ERROR] [postgres.py:update_dbms:117] Failed to execute "alter system set autovacuum_multixact_freeze_max_age to '5200';" to update dbms for error: 5200 is outside the valid range for parameter "autovacuum_multixact_freeze_max_age" (10000 .. 2000000000)

[2025-04-25 22:57:29,186 ERROR] [postgres.py:update_dbms:117] Failed to execute "alter system set track_wal_io_timing to 'off';" to update dbms for error: unrecognized configuration parameter "track_wal_io_timing"

[2025-04-25 22:58:17,737 ERROR] [postgres.py:update_dbms:117] Failed to execute "alter system set temp_buffers to '0';" to update dbms for error: 0 8kB is outside the valid range for parameter "temp_buffers" (100 .. 1073741823)

[2025-04-25 22:58:17,746 ERROR] [postgres.py:update_dbms:117] Failed to execute "alter system set track_wal_io_timing to 'on';" to update dbms for error: unrecognized configuration parameter "track_wal_io_timing"

[2025-04-25 22:58:17,830 ERROR] [postgres.py:update_dbms:117] Failed to execute "alter system set autovacuum_max_workers to '0';" to update dbms for error: 0 is outside the valid range for parameter "autovacuum_max_workers" (1 .. 262143)

[2025-04-25 23:01:25,380 ERROR] [postgres.py:update_dbms:117] Failed to execute "alter system set track_wal_io_timing to 'off';" to update dbms for error: unrecognized configuration parameter "track_wal_io_timing"

[2025-04-25 23:01:25,456 ERROR] [postgres.py:update_dbms:117] Failed to execute "alter system set autovacuum_max_workers to '0';" to update dbms for error: 0 is outside the valid range for parameter "autovacuum_max_workers" (1 .. 262143)

[2025-04-25 23:02:24,509 ERROR] [postgres.py:update_dbms:117] Failed to execute "alter system set autovacuum_multixact_freeze_max_age to '2800';" to update dbms for error: 2800 is outside the valid range for parameter "autovacuum_multixact_freeze_max_age" (10000 .. 2000000000)

[2025-04-25 23:02:24,516 ERROR] [postgres.py:update_dbms:117] Failed to execute "alter system set temp_buffers to '0';" to update dbms for error: 0 8kB is outside the valid range for parameter "temp_buffers" (100 .. 1073741823)

[2025-04-25 23:02:24,523 ERROR] [postgres.py:update_dbms:117] Failed to execute "alter system set track_wal_io_timing to 'off';" to update dbms for error: unrecognized configuration parameter "track_wal_io_timing"

[2025-04-25 23:02:24,601 ERROR] [postgres.py:update_dbms:117] Failed to execute "alter system set autovacuum_max_workers to '0';" to update dbms for error: 0 is outside the valid range for parameter "autovacuum_max_workers" (1 .. 262143)

[2025-04-25 23:03:07,984 ERROR] [postgres.py:update_dbms:117] Failed to execute "alter system set temp_buffers to '0';" to update dbms for error: 0 8kB is outside the valid range for parameter "temp_buffers" (100 .. 1073741823)

[2025-04-25 23:03:07,992 ERROR] [postgres.py:update_dbms:117] Failed to execute "alter system set track_wal_io_timing to 'on';" to update dbms for error: unrecognized configuration parameter "track_wal_io_timing"

[2025-04-25 23:03:28,310 ERROR] [postgres.py:update_dbms:117] Failed to execute "alter system reset all;" to update dbms for error: 'NoneType' object has no attribute 'autocommit'
[2025-04-25 23:03:31,160 ERROR] [postgres.py:update_dbms:117] Failed to execute "alter system set track_wal_io_timing to 'on';" to update dbms for error: unrecognized configuration parameter "track_wal_io_timing"

[2025-04-25 23:03:51,457 ERROR] [postgres.py:update_dbms:117] Failed to execute "alter system reset all;" to update dbms for error: 'NoneType' object has no attribute 'autocommit'
[2025-04-25 23:03:54,254 ERROR] [postgres.py:update_dbms:117] Failed to execute "alter system set autovacuum_multixact_freeze_max_age to '5200';" to update dbms for error: 5200 is outside the valid range for parameter "autovacuum_multixact_freeze_max_age" (10000 .. 2000000000)

[2025-04-25 23:03:54,261 ERROR] [postgres.py:update_dbms:117] Failed to execute "alter system set temp_buffers to '0';" to update dbms for error: 0 8kB is outside the valid range for parameter "temp_buffers" (100 .. 1073741823)

[2025-04-25 23:03:54,269 ERROR] [postgres.py:update_dbms:117] Failed to execute "alter system set track_wal_io_timing to 'on';" to update dbms for error: unrecognized configuration parameter "track_wal_io_timing"

[2025-04-25 23:05:24,462 ERROR] [postgres.py:update_dbms:117] Failed to execute "alter system set track_wal_io_timing to 'on';" to update dbms for error: unrecognized configuration parameter "track_wal_io_timing"

[2025-04-25 23:05:24,540 ERROR] [postgres.py:update_dbms:117] Failed to execute "alter system set autovacuum_max_workers to '0';" to update dbms for error: 0 is outside the valid range for parameter "autovacuum_max_workers" (1 .. 262143)

[2025-04-25 23:06:12,537 ERROR] [postgres.py:update_dbms:117] Failed to execute "alter system set autovacuum_multixact_freeze_max_age to '2800';" to update dbms for error: 2800 is outside the valid range for parameter "autovacuum_multixact_freeze_max_age" (10000 .. 2000000000)

[2025-04-25 23:06:12,544 ERROR] [postgres.py:update_dbms:117] Failed to execute "alter system set temp_buffers to '0';" to update dbms for error: 0 8kB is outside the valid range for parameter "temp_buffers" (100 .. 1073741823)

[2025-04-25 23:06:12,551 ERROR] [postgres.py:update_dbms:117] Failed to execute "alter system set track_wal_io_timing to 'off';" to update dbms for error: unrecognized configuration parameter "track_wal_io_timing"

[2025-04-25 23:06:12,627 ERROR] [postgres.py:update_dbms:117] Failed to execute "alter system set autovacuum_max_workers to '0';" to update dbms for error: 0 is outside the valid range for parameter "autovacuum_max_workers" (1 .. 262143)

[2025-04-25 23:07:01,877 ERROR] [postgres.py:update_dbms:117] Failed to execute "alter system set track_wal_io_timing to 'off';" to update dbms for error: unrecognized configuration parameter "track_wal_io_timing"

[2025-04-25 23:07:22,134 ERROR] [postgres.py:update_dbms:117] Failed to execute "alter system reset all;" to update dbms for error: 'NoneType' object has no attribute 'autocommit'
[2025-04-25 23:07:24,964 ERROR] [postgres.py:update_dbms:117] Failed to execute "alter system set track_wal_io_timing to 'off';" to update dbms for error: unrecognized configuration parameter "track_wal_io_timing"

[2025-04-25 23:08:00,042 ERROR] [postgres.py:update_dbms:117] Failed to execute "alter system set track_wal_io_timing to 'on';" to update dbms for error: unrecognized configuration parameter "track_wal_io_timing"

[2025-04-25 23:08:00,124 ERROR] [postgres.py:update_dbms:117] Failed to execute "alter system set autovacuum_max_workers to '0';" to update dbms for error: 0 is outside the valid range for parameter "autovacuum_max_workers" (1 .. 262143)

[2025-04-25 23:08:20,267 ERROR] [postgres.py:update_dbms:117] Failed to execute "alter system reset all;" to update dbms for error: 'NoneType' object has no attribute 'autocommit'
[2025-04-25 23:08:23,082 ERROR] [postgres.py:update_dbms:117] Failed to execute "alter system set track_wal_io_timing to 'off';" to update dbms for error: unrecognized configuration parameter "track_wal_io_timing"

[2025-04-25 23:09:10,642 ERROR] [postgres.py:update_dbms:117] Failed to execute "alter system set track_wal_io_timing to 'off';" to update dbms for error: unrecognized configuration parameter "track_wal_io_timing"

[2025-04-25 23:09:10,714 ERROR] [postgres.py:update_dbms:117] Failed to execute "alter system set autovacuum_max_workers to '0';" to update dbms for error: 0 is outside the valid range for parameter "autovacuum_max_workers" (1 .. 262143)

[2025-04-25 23:10:36,732 ERROR] [postgres.py:update_dbms:117] Failed to execute "alter system set autovacuum_multixact_freeze_max_age to '2800';" to update dbms for error: 2800 is outside the valid range for parameter "autovacuum_multixact_freeze_max_age" (10000 .. 2000000000)

[2025-04-25 23:10:36,749 ERROR] [postgres.py:update_dbms:117] Failed to execute "alter system set track_wal_io_timing to 'off';" to update dbms for error: unrecognized configuration parameter "track_wal_io_timing"

[2025-04-25 23:10:36,821 ERROR] [postgres.py:update_dbms:117] Failed to execute "alter system set autovacuum_max_workers to '0';" to update dbms for error: 0 is outside the valid range for parameter "autovacuum_max_workers" (1 .. 262143)

[2025-04-25 23:10:57,014 ERROR] [postgres.py:update_dbms:117] Failed to execute "alter system reset all;" to update dbms for error: 'NoneType' object has no attribute 'autocommit'
[2025-04-25 23:10:59,861 ERROR] [postgres.py:update_dbms:117] Failed to execute "alter system set track_wal_io_timing to 'off';" to update dbms for error: unrecognized configuration parameter "track_wal_io_timing"

[2025-04-25 23:10:59,942 ERROR] [postgres.py:update_dbms:117] Failed to execute "alter system set autovacuum_max_workers to '0';" to update dbms for error: 0 is outside the valid range for parameter "autovacuum_max_workers" (1 .. 262143)

[2025-04-25 23:11:20,104 ERROR] [postgres.py:update_dbms:117] Failed to execute "alter system reset all;" to update dbms for error: 'NoneType' object has no attribute 'autocommit'
[2025-04-25 23:11:22,906 ERROR] [postgres.py:update_dbms:117] Failed to execute "alter system set autovacuum_multixact_freeze_max_age to '2800';" to update dbms for error: 2800 is outside the valid range for parameter "autovacuum_multixact_freeze_max_age" (10000 .. 2000000000)

[2025-04-25 23:11:22,925 ERROR] [postgres.py:update_dbms:117] Failed to execute "alter system set track_wal_io_timing to 'on';" to update dbms for error: unrecognized configuration parameter "track_wal_io_timing"

[2025-04-25 23:11:43,160 ERROR] [postgres.py:update_dbms:117] Failed to execute "alter system reset all;" to update dbms for error: 'NoneType' object has no attribute 'autocommit'
[2025-04-25 23:11:45,973 ERROR] [postgres.py:update_dbms:117] Failed to execute "alter system set track_wal_io_timing to 'on';" to update dbms for error: unrecognized configuration parameter "track_wal_io_timing"

[2025-04-25 23:13:08,885 ERROR] [postgres.py:update_dbms:117] Failed to execute "alter system set track_wal_io_timing to 'on';" to update dbms for error: unrecognized configuration parameter "track_wal_io_timing"

[2025-04-25 23:13:55,515 ERROR] [postgres.py:update_dbms:117] Failed to execute "alter system set autovacuum_multixact_freeze_max_age to '5200';" to update dbms for error: 5200 is outside the valid range for parameter "autovacuum_multixact_freeze_max_age" (10000 .. 2000000000)

[2025-04-25 23:13:55,530 ERROR] [postgres.py:update_dbms:117] Failed to execute "alter system set track_wal_io_timing to 'off';" to update dbms for error: unrecognized configuration parameter "track_wal_io_timing"

[2025-04-25 23:14:53,081 ERROR] [postgres.py:update_dbms:117] Failed to execute "alter system set track_wal_io_timing to 'off';" to update dbms for error: unrecognized configuration parameter "track_wal_io_timing"

[2025-04-25 23:15:57,927 ERROR] [postgres.py:update_dbms:117] Failed to execute "alter system set track_wal_io_timing to 'off';" to update dbms for error: unrecognized configuration parameter "track_wal_io_timing"

[2025-04-25 23:15:58,007 ERROR] [postgres.py:update_dbms:117] Failed to execute "alter system set autovacuum_max_workers to '0';" to update dbms for error: 0 is outside the valid range for parameter "autovacuum_max_workers" (1 .. 262143)

[2025-04-25 23:19:05,730 ERROR] [postgres.py:update_dbms:117] Failed to execute "alter system set track_wal_io_timing to 'off';" to update dbms for error: unrecognized configuration parameter "track_wal_io_timing"

[2025-04-25 23:19:05,811 ERROR] [postgres.py:update_dbms:117] Failed to execute "alter system set autovacuum_max_workers to '0';" to update dbms for error: 0 is outside the valid range for parameter "autovacuum_max_workers" (1 .. 262143)

[2025-04-25 23:20:12,606 ERROR] [postgres.py:update_dbms:117] Failed to execute "alter system set track_wal_io_timing to 'off';" to update dbms for error: unrecognized configuration parameter "track_wal_io_timing"

[2025-04-25 23:20:12,679 ERROR] [postgres.py:update_dbms:117] Failed to execute "alter system set autovacuum_max_workers to '0';" to update dbms for error: 0 is outside the valid range for parameter "autovacuum_max_workers" (1 .. 262143)

[2025-04-25 23:23:20,443 ERROR] [postgres.py:update_dbms:117] Failed to execute "alter system set track_wal_io_timing to 'off';" to update dbms for error: unrecognized configuration parameter "track_wal_io_timing"

[2025-04-25 23:26:28,049 ERROR] [postgres.py:update_dbms:117] Failed to execute "alter system set autovacuum_multixact_freeze_max_age to '5200';" to update dbms for error: 5200 is outside the valid range for parameter "autovacuum_multixact_freeze_max_age" (10000 .. 2000000000)

[2025-04-25 23:26:28,057 ERROR] [postgres.py:update_dbms:117] Failed to execute "alter system set temp_buffers to '0';" to update dbms for error: 0 8kB is outside the valid range for parameter "temp_buffers" (100 .. 1073741823)

[2025-04-25 23:26:28,066 ERROR] [postgres.py:update_dbms:117] Failed to execute "alter system set track_wal_io_timing to 'off';" to update dbms for error: unrecognized configuration parameter "track_wal_io_timing"

[2025-04-25 23:27:35,246 ERROR] [postgres.py:update_dbms:117] Failed to execute "alter system set autovacuum_multixact_freeze_max_age to '2800';" to update dbms for error: 2800 is outside the valid range for parameter "autovacuum_multixact_freeze_max_age" (10000 .. 2000000000)

[2025-04-25 23:27:35,252 ERROR] [postgres.py:update_dbms:117] Failed to execute "alter system set temp_buffers to '0';" to update dbms for error: 0 8kB is outside the valid range for parameter "temp_buffers" (100 .. 1073741823)

[2025-04-25 23:27:35,259 ERROR] [postgres.py:update_dbms:117] Failed to execute "alter system set track_wal_io_timing to 'off';" to update dbms for error: unrecognized configuration parameter "track_wal_io_timing"

[2025-04-25 23:28:49,853 ERROR] [postgres.py:update_dbms:117] Failed to execute "alter system set autovacuum_multixact_freeze_max_age to '5200';" to update dbms for error: 5200 is outside the valid range for parameter "autovacuum_multixact_freeze_max_age" (10000 .. 2000000000)

[2025-04-25 23:28:49,868 ERROR] [postgres.py:update_dbms:117] Failed to execute "alter system set track_wal_io_timing to 'off';" to update dbms for error: unrecognized configuration parameter "track_wal_io_timing"

[2025-04-25 23:29:11,571 ERROR] [postgres.py:update_dbms:117] Failed to execute "alter system reset all;" to update dbms for error: 'NoneType' object has no attribute 'autocommit'
[2025-04-25 23:29:14,385 ERROR] [postgres.py:update_dbms:117] Failed to execute "alter system set track_wal_io_timing to 'off';" to update dbms for error: unrecognized configuration parameter "track_wal_io_timing"

[2025-04-25 23:29:14,461 ERROR] [postgres.py:update_dbms:117] Failed to execute "alter system set autovacuum_max_workers to '0';" to update dbms for error: 0 is outside the valid range for parameter "autovacuum_max_workers" (1 .. 262143)

[2025-04-25 23:30:35,865 ERROR] [postgres.py:update_dbms:117] Failed to execute "alter system set autovacuum_multixact_freeze_max_age to '5200';" to update dbms for error: 5200 is outside the valid range for parameter "autovacuum_multixact_freeze_max_age" (10000 .. 2000000000)

[2025-04-25 23:30:35,882 ERROR] [postgres.py:update_dbms:117] Failed to execute "alter system set track_wal_io_timing to 'on';" to update dbms for error: unrecognized configuration parameter "track_wal_io_timing"

[2025-04-25 23:30:35,961 ERROR] [postgres.py:update_dbms:117] Failed to execute "alter system set autovacuum_max_workers to '0';" to update dbms for error: 0 is outside the valid range for parameter "autovacuum_max_workers" (1 .. 262143)

[2025-04-25 23:31:41,365 ERROR] [postgres.py:update_dbms:117] Failed to execute "alter system set autovacuum_multixact_freeze_max_age to '5200';" to update dbms for error: 5200 is outside the valid range for parameter "autovacuum_multixact_freeze_max_age" (10000 .. 2000000000)

[2025-04-25 23:31:41,383 ERROR] [postgres.py:update_dbms:117] Failed to execute "alter system set track_wal_io_timing to 'on';" to update dbms for error: unrecognized configuration parameter "track_wal_io_timing"

[2025-04-25 23:31:41,465 ERROR] [postgres.py:update_dbms:117] Failed to execute "alter system set autovacuum_max_workers to '0';" to update dbms for error: 0 is outside the valid range for parameter "autovacuum_max_workers" (1 .. 262143)

[2025-04-25 23:32:25,030 ERROR] [postgres.py:update_dbms:117] Failed to execute "alter system set temp_buffers to '0';" to update dbms for error: 0 8kB is outside the valid range for parameter "temp_buffers" (100 .. 1073741823)

[2025-04-25 23:32:25,038 ERROR] [postgres.py:update_dbms:117] Failed to execute "alter system set track_wal_io_timing to 'on';" to update dbms for error: unrecognized configuration parameter "track_wal_io_timing"

[2025-04-25 23:32:25,116 ERROR] [postgres.py:update_dbms:117] Failed to execute "alter system set autovacuum_max_workers to '0';" to update dbms for error: 0 is outside the valid range for parameter "autovacuum_max_workers" (1 .. 262143)

[2025-04-25 23:32:56,935 ERROR] [postgres.py:update_dbms:117] Failed to execute "alter system set track_wal_io_timing to 'off';" to update dbms for error: unrecognized configuration parameter "track_wal_io_timing"

[2025-04-25 23:33:28,151 ERROR] [postgres.py:update_dbms:117] Failed to execute "alter system set track_wal_io_timing to 'on';" to update dbms for error: unrecognized configuration parameter "track_wal_io_timing"

[2025-04-25 23:33:28,224 ERROR] [postgres.py:update_dbms:117] Failed to execute "alter system set autovacuum_max_workers to '0';" to update dbms for error: 0 is outside the valid range for parameter "autovacuum_max_workers" (1 .. 262143)

[2025-04-25 23:36:36,071 ERROR] [postgres.py:update_dbms:117] Failed to execute "alter system set temp_buffers to '0';" to update dbms for error: 0 8kB is outside the valid range for parameter "temp_buffers" (100 .. 1073741823)

[2025-04-25 23:36:36,078 ERROR] [postgres.py:update_dbms:117] Failed to execute "alter system set track_wal_io_timing to 'off';" to update dbms for error: unrecognized configuration parameter "track_wal_io_timing"

[2025-04-25 23:37:25,738 ERROR] [postgres.py:update_dbms:117] Failed to execute "alter system set temp_buffers to '0';" to update dbms for error: 0 8kB is outside the valid range for parameter "temp_buffers" (100 .. 1073741823)

[2025-04-25 23:37:25,746 ERROR] [postgres.py:update_dbms:117] Failed to execute "alter system set track_wal_io_timing to 'off';" to update dbms for error: unrecognized configuration parameter "track_wal_io_timing"

[2025-04-25 23:37:25,826 ERROR] [postgres.py:update_dbms:117] Failed to execute "alter system set autovacuum_max_workers to '0';" to update dbms for error: 0 is outside the valid range for parameter "autovacuum_max_workers" (1 .. 262143)

[2025-04-25 23:38:14,048 ERROR] [postgres.py:update_dbms:117] Failed to execute "alter system set autovacuum_multixact_freeze_max_age to '2800';" to update dbms for error: 2800 is outside the valid range for parameter "autovacuum_multixact_freeze_max_age" (10000 .. 2000000000)

[2025-04-25 23:38:14,065 ERROR] [postgres.py:update_dbms:117] Failed to execute "alter system set track_wal_io_timing to 'off';" to update dbms for error: unrecognized configuration parameter "track_wal_io_timing"

[2025-04-25 23:39:27,224 ERROR] [postgres.py:update_dbms:117] Failed to execute "alter system set temp_buffers to '0';" to update dbms for error: 0 8kB is outside the valid range for parameter "temp_buffers" (100 .. 1073741823)

[2025-04-25 23:39:27,232 ERROR] [postgres.py:update_dbms:117] Failed to execute "alter system set track_wal_io_timing to 'off';" to update dbms for error: unrecognized configuration parameter "track_wal_io_timing"

[2025-04-25 23:39:27,302 ERROR] [postgres.py:update_dbms:117] Failed to execute "alter system set autovacuum_max_workers to '0';" to update dbms for error: 0 is outside the valid range for parameter "autovacuum_max_workers" (1 .. 262143)

[2025-04-25 23:42:36,677 ERROR] [postgres.py:update_dbms:117] Failed to execute "alter system set temp_buffers to '0';" to update dbms for error: 0 8kB is outside the valid range for parameter "temp_buffers" (100 .. 1073741823)

[2025-04-25 23:42:36,685 ERROR] [postgres.py:update_dbms:117] Failed to execute "alter system set track_wal_io_timing to 'on';" to update dbms for error: unrecognized configuration parameter "track_wal_io_timing"

[2025-04-25 23:43:14,261 ERROR] [postgres.py:update_dbms:117] Failed to execute "alter system set autovacuum_multixact_freeze_max_age to '5200';" to update dbms for error: 5200 is outside the valid range for parameter "autovacuum_multixact_freeze_max_age" (10000 .. 2000000000)

[2025-04-25 23:43:14,269 ERROR] [postgres.py:update_dbms:117] Failed to execute "alter system set temp_buffers to '0';" to update dbms for error: 0 8kB is outside the valid range for parameter "temp_buffers" (100 .. 1073741823)

[2025-04-25 23:43:14,277 ERROR] [postgres.py:update_dbms:117] Failed to execute "alter system set track_wal_io_timing to 'on';" to update dbms for error: unrecognized configuration parameter "track_wal_io_timing"

[2025-04-25 23:43:14,354 ERROR] [postgres.py:update_dbms:117] Failed to execute "alter system set autovacuum_max_workers to '0';" to update dbms for error: 0 is outside the valid range for parameter "autovacuum_max_workers" (1 .. 262143)

[2025-04-25 23:43:45,832 ERROR] [postgres.py:update_dbms:117] Failed to execute "alter system set track_wal_io_timing to 'on';" to update dbms for error: unrecognized configuration parameter "track_wal_io_timing"

[2025-04-25 23:43:45,910 ERROR] [postgres.py:update_dbms:117] Failed to execute "alter system set autovacuum_max_workers to '0';" to update dbms for error: 0 is outside the valid range for parameter "autovacuum_max_workers" (1 .. 262143)

[2025-04-25 23:44:16,936 ERROR] [postgres.py:update_dbms:117] Failed to execute "alter system set temp_buffers to '0';" to update dbms for error: 0 8kB is outside the valid range for parameter "temp_buffers" (100 .. 1073741823)

[2025-04-25 23:44:16,943 ERROR] [postgres.py:update_dbms:117] Failed to execute "alter system set track_wal_io_timing to 'on';" to update dbms for error: unrecognized configuration parameter "track_wal_io_timing"

[2025-04-25 23:44:55,051 ERROR] [postgres.py:update_dbms:117] Failed to execute "alter system set track_wal_io_timing to 'on';" to update dbms for error: unrecognized configuration parameter "track_wal_io_timing"

[2025-04-25 23:45:24,372 ERROR] [postgres.py:update_dbms:117] Failed to execute "alter system set track_wal_io_timing to 'on';" to update dbms for error: unrecognized configuration parameter "track_wal_io_timing"

[2025-04-25 23:46:20,037 ERROR] [postgres.py:update_dbms:117] Failed to execute "alter system set temp_buffers to '0';" to update dbms for error: 0 8kB is outside the valid range for parameter "temp_buffers" (100 .. 1073741823)

[2025-04-25 23:46:20,045 ERROR] [postgres.py:update_dbms:117] Failed to execute "alter system set track_wal_io_timing to 'off';" to update dbms for error: unrecognized configuration parameter "track_wal_io_timing"

[2025-04-25 23:47:07,233 ERROR] [postgres.py:update_dbms:117] Failed to execute "alter system set temp_buffers to '0';" to update dbms for error: 0 8kB is outside the valid range for parameter "temp_buffers" (100 .. 1073741823)

[2025-04-25 23:47:07,240 ERROR] [postgres.py:update_dbms:117] Failed to execute "alter system set track_wal_io_timing to 'off';" to update dbms for error: unrecognized configuration parameter "track_wal_io_timing"

[2025-04-25 23:47:55,739 ERROR] [postgres.py:update_dbms:117] Failed to execute "alter system set track_wal_io_timing to 'off';" to update dbms for error: unrecognized configuration parameter "track_wal_io_timing"

[2025-04-25 23:48:17,970 ERROR] [postgres.py:update_dbms:117] Failed to execute "alter system reset all;" to update dbms for error: 'NoneType' object has no attribute 'autocommit'
[2025-04-25 23:48:20,784 ERROR] [postgres.py:update_dbms:117] Failed to execute "alter system set temp_buffers to '0';" to update dbms for error: 0 8kB is outside the valid range for parameter "temp_buffers" (100 .. 1073741823)

[2025-04-25 23:48:20,790 ERROR] [postgres.py:update_dbms:117] Failed to execute "alter system set track_wal_io_timing to 'on';" to update dbms for error: unrecognized configuration parameter "track_wal_io_timing"

[2025-04-25 23:48:20,863 ERROR] [postgres.py:update_dbms:117] Failed to execute "alter system set autovacuum_max_workers to '0';" to update dbms for error: 0 is outside the valid range for parameter "autovacuum_max_workers" (1 .. 262143)

[2025-04-25 23:48:41,112 ERROR] [postgres.py:update_dbms:117] Failed to execute "alter system reset all;" to update dbms for error: 'NoneType' object has no attribute 'autocommit'
[2025-04-25 23:48:43,938 ERROR] [postgres.py:update_dbms:117] Failed to execute "alter system set track_wal_io_timing to 'on';" to update dbms for error: unrecognized configuration parameter "track_wal_io_timing"

[2025-04-25 23:48:44,025 ERROR] [postgres.py:update_dbms:117] Failed to execute "alter system set autovacuum_max_workers to '0';" to update dbms for error: 0 is outside the valid range for parameter "autovacuum_max_workers" (1 .. 262143)

[2025-04-25 23:49:23,633 ERROR] [postgres.py:update_dbms:117] Failed to execute "alter system set track_wal_io_timing to 'on';" to update dbms for error: unrecognized configuration parameter "track_wal_io_timing"

[2025-04-25 23:49:23,706 ERROR] [postgres.py:update_dbms:117] Failed to execute "alter system set autovacuum_max_workers to '0';" to update dbms for error: 0 is outside the valid range for parameter "autovacuum_max_workers" (1 .. 262143)

[2025-04-25 23:49:52,716 ERROR] [postgres.py:update_dbms:117] Failed to execute "alter system set track_wal_io_timing to 'off';" to update dbms for error: unrecognized configuration parameter "track_wal_io_timing"

[2025-04-25 23:49:52,801 ERROR] [postgres.py:update_dbms:117] Failed to execute "alter system set autovacuum_max_workers to '0';" to update dbms for error: 0 is outside the valid range for parameter "autovacuum_max_workers" (1 .. 262143)

[2025-04-25 23:50:23,661 ERROR] [postgres.py:update_dbms:117] Failed to execute "alter system set track_wal_io_timing to 'on';" to update dbms for error: unrecognized configuration parameter "track_wal_io_timing"

[2025-04-25 23:50:23,733 ERROR] [postgres.py:update_dbms:117] Failed to execute "alter system set autovacuum_max_workers to '0';" to update dbms for error: 0 is outside the valid range for parameter "autovacuum_max_workers" (1 .. 262143)

[2025-04-25 23:51:03,790 ERROR] [postgres.py:update_dbms:117] Failed to execute "alter system set track_wal_io_timing to 'on';" to update dbms for error: unrecognized configuration parameter "track_wal_io_timing"

[2025-04-25 23:51:24,094 ERROR] [postgres.py:update_dbms:117] Failed to execute "alter system reset all;" to update dbms for error: 'NoneType' object has no attribute 'autocommit'
[2025-04-25 23:51:26,927 ERROR] [postgres.py:update_dbms:117] Failed to execute "alter system set temp_buffers to '0';" to update dbms for error: 0 8kB is outside the valid range for parameter "temp_buffers" (100 .. 1073741823)

[2025-04-25 23:51:26,935 ERROR] [postgres.py:update_dbms:117] Failed to execute "alter system set track_wal_io_timing to 'on';" to update dbms for error: unrecognized configuration parameter "track_wal_io_timing"

[2025-04-25 23:52:38,185 ERROR] [postgres.py:update_dbms:117] Failed to execute "alter system set track_wal_io_timing to 'off';" to update dbms for error: unrecognized configuration parameter "track_wal_io_timing"

[2025-04-25 23:52:38,267 ERROR] [postgres.py:update_dbms:117] Failed to execute "alter system set autovacuum_max_workers to '0';" to update dbms for error: 0 is outside the valid range for parameter "autovacuum_max_workers" (1 .. 262143)

[2025-04-25 23:55:47,713 ERROR] [postgres.py:update_dbms:117] Failed to execute "alter system set track_wal_io_timing to 'on';" to update dbms for error: unrecognized configuration parameter "track_wal_io_timing"

[2025-04-25 23:55:47,787 ERROR] [postgres.py:update_dbms:117] Failed to execute "alter system set autovacuum_max_workers to '0';" to update dbms for error: 0 is outside the valid range for parameter "autovacuum_max_workers" (1 .. 262143)

[2025-04-25 23:56:18,172 ERROR] [postgres.py:update_dbms:117] Failed to execute "alter system set track_wal_io_timing to 'on';" to update dbms for error: unrecognized configuration parameter "track_wal_io_timing"

[2025-04-25 23:56:18,253 ERROR] [postgres.py:update_dbms:117] Failed to execute "alter system set autovacuum_max_workers to '0';" to update dbms for error: 0 is outside the valid range for parameter "autovacuum_max_workers" (1 .. 262143)

[2025-04-25 23:56:38,473 ERROR] [postgres.py:update_dbms:117] Failed to execute "alter system reset all;" to update dbms for error: 'NoneType' object has no attribute 'autocommit'
[2025-04-25 23:56:41,316 ERROR] [postgres.py:update_dbms:117] Failed to execute "alter system set track_wal_io_timing to 'off';" to update dbms for error: unrecognized configuration parameter "track_wal_io_timing"

[2025-04-25 23:56:41,397 ERROR] [postgres.py:update_dbms:117] Failed to execute "alter system set autovacuum_max_workers to '0';" to update dbms for error: 0 is outside the valid range for parameter "autovacuum_max_workers" (1 .. 262143)

[2025-04-25 23:57:10,550 ERROR] [postgres.py:update_dbms:117] Failed to execute "alter system set track_wal_io_timing to 'on';" to update dbms for error: unrecognized configuration parameter "track_wal_io_timing"

[2025-04-25 23:57:10,627 ERROR] [postgres.py:update_dbms:117] Failed to execute "alter system set autovacuum_max_workers to '0';" to update dbms for error: 0 is outside the valid range for parameter "autovacuum_max_workers" (1 .. 262143)

[2025-04-25 23:57:39,795 ERROR] [postgres.py:update_dbms:117] Failed to execute "alter system set track_wal_io_timing to 'off';" to update dbms for error: unrecognized configuration parameter "track_wal_io_timing"

[2025-04-25 23:58:08,170 ERROR] [postgres.py:update_dbms:117] Failed to execute "alter system set temp_buffers to '0';" to update dbms for error: 0 8kB is outside the valid range for parameter "temp_buffers" (100 .. 1073741823)

[2025-04-25 23:58:08,177 ERROR] [postgres.py:update_dbms:117] Failed to execute "alter system set track_wal_io_timing to 'off';" to update dbms for error: unrecognized configuration parameter "track_wal_io_timing"

[2025-04-25 23:58:08,258 ERROR] [postgres.py:update_dbms:117] Failed to execute "alter system set autovacuum_max_workers to '0';" to update dbms for error: 0 is outside the valid range for parameter "autovacuum_max_workers" (1 .. 262143)

[2025-04-25 23:58:38,979 ERROR] [postgres.py:update_dbms:117] Failed to execute "alter system set track_wal_io_timing to 'on';" to update dbms for error: unrecognized configuration parameter "track_wal_io_timing"

[2025-04-25 23:59:11,794 ERROR] [postgres.py:update_dbms:117] Failed to execute "alter system set temp_buffers to '0';" to update dbms for error: 0 8kB is outside the valid range for parameter "temp_buffers" (100 .. 1073741823)

[2025-04-25 23:59:11,803 ERROR] [postgres.py:update_dbms:117] Failed to execute "alter system set track_wal_io_timing to 'off';" to update dbms for error: unrecognized configuration parameter "track_wal_io_timing"

[2025-04-25 23:59:41,395 ERROR] [postgres.py:update_dbms:117] Failed to execute "alter system set temp_buffers to '0';" to update dbms for error: 0 8kB is outside the valid range for parameter "temp_buffers" (100 .. 1073741823)

[2025-04-25 23:59:41,402 ERROR] [postgres.py:update_dbms:117] Failed to execute "alter system set track_wal_io_timing to 'off';" to update dbms for error: unrecognized configuration parameter "track_wal_io_timing"

[2025-04-26 00:00:23,506 ERROR] [postgres.py:update_dbms:117] Failed to execute "alter system set temp_buffers to '0';" to update dbms for error: 0 8kB is outside the valid range for parameter "temp_buffers" (100 .. 1073741823)

[2025-04-26 00:00:23,513 ERROR] [postgres.py:update_dbms:117] Failed to execute "alter system set track_wal_io_timing to 'off';" to update dbms for error: unrecognized configuration parameter "track_wal_io_timing"

[2025-04-26 00:01:14,809 ERROR] [postgres.py:update_dbms:117] Failed to execute "alter system set temp_buffers to '0';" to update dbms for error: 0 8kB is outside the valid range for parameter "temp_buffers" (100 .. 1073741823)

[2025-04-26 00:01:14,815 ERROR] [postgres.py:update_dbms:117] Failed to execute "alter system set track_wal_io_timing to 'on';" to update dbms for error: unrecognized configuration parameter "track_wal_io_timing"

[2025-04-26 00:01:14,892 ERROR] [postgres.py:update_dbms:117] Failed to execute "alter system set autovacuum_max_workers to '0';" to update dbms for error: 0 is outside the valid range for parameter "autovacuum_max_workers" (1 .. 262143)

[2025-04-26 00:01:49,168 ERROR] [postgres.py:update_dbms:117] Failed to execute "alter system set autovacuum_multixact_freeze_max_age to '5200';" to update dbms for error: 5200 is outside the valid range for parameter "autovacuum_multixact_freeze_max_age" (10000 .. 2000000000)

[2025-04-26 00:01:49,185 ERROR] [postgres.py:update_dbms:117] Failed to execute "alter system set track_wal_io_timing to 'on';" to update dbms for error: unrecognized configuration parameter "track_wal_io_timing"

[2025-04-26 00:02:20,638 ERROR] [postgres.py:update_dbms:117] Failed to execute "alter system set track_wal_io_timing to 'on';" to update dbms for error: unrecognized configuration parameter "track_wal_io_timing"

[2025-04-26 00:02:51,389 ERROR] [postgres.py:update_dbms:117] Failed to execute "alter system set autovacuum_multixact_freeze_max_age to '5200';" to update dbms for error: 5200 is outside the valid range for parameter "autovacuum_multixact_freeze_max_age" (10000 .. 2000000000)

[2025-04-26 00:02:51,396 ERROR] [postgres.py:update_dbms:117] Failed to execute "alter system set temp_buffers to '0';" to update dbms for error: 0 8kB is outside the valid range for parameter "temp_buffers" (100 .. 1073741823)

[2025-04-26 00:02:51,403 ERROR] [postgres.py:update_dbms:117] Failed to execute "alter system set track_wal_io_timing to 'off';" to update dbms for error: unrecognized configuration parameter "track_wal_io_timing"

[2025-04-26 00:02:51,479 ERROR] [postgres.py:update_dbms:117] Failed to execute "alter system set autovacuum_max_workers to '0';" to update dbms for error: 0 is outside the valid range for parameter "autovacuum_max_workers" (1 .. 262143)

[2025-04-26 00:03:23,975 ERROR] [postgres.py:update_dbms:117] Failed to execute "alter system set temp_buffers to '0';" to update dbms for error: 0 8kB is outside the valid range for parameter "temp_buffers" (100 .. 1073741823)

[2025-04-26 00:03:23,983 ERROR] [postgres.py:update_dbms:117] Failed to execute "alter system set track_wal_io_timing to 'off';" to update dbms for error: unrecognized configuration parameter "track_wal_io_timing"

[2025-04-26 00:03:58,329 ERROR] [postgres.py:update_dbms:117] Failed to execute "alter system set track_wal_io_timing to 'off';" to update dbms for error: unrecognized configuration parameter "track_wal_io_timing"

[2025-04-26 00:04:28,928 ERROR] [postgres.py:update_dbms:117] Failed to execute "alter system set track_wal_io_timing to 'off';" to update dbms for error: unrecognized configuration parameter "track_wal_io_timing"

[2025-04-26 00:05:01,530 ERROR] [postgres.py:update_dbms:117] Failed to execute "alter system set track_wal_io_timing to 'on';" to update dbms for error: unrecognized configuration parameter "track_wal_io_timing"

[2025-04-26 00:05:30,293 ERROR] [postgres.py:update_dbms:117] Failed to execute "alter system set temp_buffers to '0';" to update dbms for error: 0 8kB is outside the valid range for parameter "temp_buffers" (100 .. 1073741823)

[2025-04-26 00:05:30,300 ERROR] [postgres.py:update_dbms:117] Failed to execute "alter system set track_wal_io_timing to 'off';" to update dbms for error: unrecognized configuration parameter "track_wal_io_timing"

[2025-04-26 00:05:30,383 ERROR] [postgres.py:update_dbms:117] Failed to execute "alter system set autovacuum_max_workers to '0';" to update dbms for error: 0 is outside the valid range for parameter "autovacuum_max_workers" (1 .. 262143)

[2025-04-26 00:06:24,540 ERROR] [postgres.py:update_dbms:117] Failed to execute "alter system set track_wal_io_timing to 'off';" to update dbms for error: unrecognized configuration parameter "track_wal_io_timing"

[2025-04-26 00:06:54,464 ERROR] [postgres.py:update_dbms:117] Failed to execute "alter system set track_wal_io_timing to 'off';" to update dbms for error: unrecognized configuration parameter "track_wal_io_timing"

[2025-04-26 00:07:14,755 ERROR] [postgres.py:update_dbms:117] Failed to execute "alter system reset all;" to update dbms for error: 'NoneType' object has no attribute 'autocommit'
[2025-04-26 00:07:17,570 ERROR] [postgres.py:update_dbms:117] Failed to execute "alter system set track_wal_io_timing to 'on';" to update dbms for error: unrecognized configuration parameter "track_wal_io_timing"

[2025-04-26 00:10:25,375 ERROR] [postgres.py:update_dbms:117] Failed to execute "alter system set track_wal_io_timing to 'off';" to update dbms for error: unrecognized configuration parameter "track_wal_io_timing"

[2025-04-26 00:10:25,463 ERROR] [postgres.py:update_dbms:117] Failed to execute "alter system set autovacuum_max_workers to '0';" to update dbms for error: 0 is outside the valid range for parameter "autovacuum_max_workers" (1 .. 262143)

[2025-04-26 00:11:25,679 ERROR] [postgres.py:update_dbms:117] Failed to execute "alter system set track_wal_io_timing to 'on';" to update dbms for error: unrecognized configuration parameter "track_wal_io_timing"

[2025-04-26 00:11:53,943 ERROR] [postgres.py:update_dbms:117] Failed to execute "alter system set track_wal_io_timing to 'off';" to update dbms for error: unrecognized configuration parameter "track_wal_io_timing"

[2025-04-26 00:12:22,908 ERROR] [postgres.py:update_dbms:117] Failed to execute "alter system set track_wal_io_timing to 'off';" to update dbms for error: unrecognized configuration parameter "track_wal_io_timing"

[2025-04-26 00:12:52,910 ERROR] [postgres.py:update_dbms:117] Failed to execute "alter system set temp_buffers to '0';" to update dbms for error: 0 8kB is outside the valid range for parameter "temp_buffers" (100 .. 1073741823)

[2025-04-26 00:12:52,917 ERROR] [postgres.py:update_dbms:117] Failed to execute "alter system set track_wal_io_timing to 'on';" to update dbms for error: unrecognized configuration parameter "track_wal_io_timing"

[2025-04-26 00:13:22,263 ERROR] [postgres.py:update_dbms:117] Failed to execute "alter system set track_wal_io_timing to 'on';" to update dbms for error: unrecognized configuration parameter "track_wal_io_timing"

[2025-04-26 00:13:52,366 ERROR] [postgres.py:update_dbms:117] Failed to execute "alter system set track_wal_io_timing to 'on';" to update dbms for error: unrecognized configuration parameter "track_wal_io_timing"

[2025-04-26 00:14:48,853 ERROR] [postgres.py:update_dbms:117] Failed to execute "alter system set track_wal_io_timing to 'on';" to update dbms for error: unrecognized configuration parameter "track_wal_io_timing"

[2025-04-26 00:15:22,444 ERROR] [postgres.py:update_dbms:117] Failed to execute "alter system set temp_buffers to '0';" to update dbms for error: 0 8kB is outside the valid range for parameter "temp_buffers" (100 .. 1073741823)

[2025-04-26 00:15:22,452 ERROR] [postgres.py:update_dbms:117] Failed to execute "alter system set track_wal_io_timing to 'off';" to update dbms for error: unrecognized configuration parameter "track_wal_io_timing"

[2025-04-26 00:15:44,981 ERROR] [postgres.py:update_dbms:117] Failed to execute "alter system reset all;" to update dbms for error: 'NoneType' object has no attribute 'autocommit'
[2025-04-26 00:15:47,799 ERROR] [postgres.py:update_dbms:117] Failed to execute "alter system set track_wal_io_timing to 'off';" to update dbms for error: unrecognized configuration parameter "track_wal_io_timing"

[2025-04-26 00:16:20,612 ERROR] [postgres.py:update_dbms:117] Failed to execute "alter system set track_wal_io_timing to 'on';" to update dbms for error: unrecognized configuration parameter "track_wal_io_timing"

[2025-04-26 00:16:53,349 ERROR] [postgres.py:update_dbms:117] Failed to execute "alter system set track_wal_io_timing to 'off';" to update dbms for error: unrecognized configuration parameter "track_wal_io_timing"

[2025-04-26 00:16:53,426 ERROR] [postgres.py:update_dbms:117] Failed to execute "alter system set autovacuum_max_workers to '0';" to update dbms for error: 0 is outside the valid range for parameter "autovacuum_max_workers" (1 .. 262143)

[2025-04-26 00:17:24,793 ERROR] [postgres.py:update_dbms:117] Failed to execute "alter system set track_wal_io_timing to 'on';" to update dbms for error: unrecognized configuration parameter "track_wal_io_timing"

[2025-04-26 00:18:11,236 ERROR] [postgres.py:update_dbms:117] Failed to execute "alter system set track_wal_io_timing to 'on';" to update dbms for error: unrecognized configuration parameter "track_wal_io_timing"

[2025-04-26 00:21:19,438 ERROR] [postgres.py:update_dbms:117] Failed to execute "alter system set track_wal_io_timing to 'off';" to update dbms for error: unrecognized configuration parameter "track_wal_io_timing"

[2025-04-26 00:24:30,716 ERROR] [postgres.py:update_dbms:117] Failed to execute "alter system set track_wal_io_timing to 'off';" to update dbms for error: unrecognized configuration parameter "track_wal_io_timing"

[2025-04-26 00:24:58,938 ERROR] [postgres.py:update_dbms:117] Failed to execute "alter system set temp_buffers to '0';" to update dbms for error: 0 8kB is outside the valid range for parameter "temp_buffers" (100 .. 1073741823)

[2025-04-26 00:24:58,946 ERROR] [postgres.py:update_dbms:117] Failed to execute "alter system set track_wal_io_timing to 'off';" to update dbms for error: unrecognized configuration parameter "track_wal_io_timing"

[2025-04-26 00:24:59,022 ERROR] [postgres.py:update_dbms:117] Failed to execute "alter system set autovacuum_max_workers to '0';" to update dbms for error: 0 is outside the valid range for parameter "autovacuum_max_workers" (1 .. 262143)

[2025-04-26 00:25:19,396 ERROR] [postgres.py:update_dbms:117] Failed to execute "alter system reset all;" to update dbms for error: 'NoneType' object has no attribute 'autocommit'
[2025-04-26 00:25:22,217 ERROR] [postgres.py:update_dbms:117] Failed to execute "alter system set temp_buffers to '0';" to update dbms for error: 0 8kB is outside the valid range for parameter "temp_buffers" (100 .. 1073741823)

[2025-04-26 00:25:22,224 ERROR] [postgres.py:update_dbms:117] Failed to execute "alter system set track_wal_io_timing to 'off';" to update dbms for error: unrecognized configuration parameter "track_wal_io_timing"

[2025-04-26 00:25:22,304 ERROR] [postgres.py:update_dbms:117] Failed to execute "alter system set autovacuum_max_workers to '0';" to update dbms for error: 0 is outside the valid range for parameter "autovacuum_max_workers" (1 .. 262143)

[2025-04-26 00:25:44,539 ERROR] [postgres.py:update_dbms:117] Failed to execute "alter system reset all;" to update dbms for error: 'NoneType' object has no attribute 'autocommit'
[2025-04-26 00:25:47,365 ERROR] [postgres.py:update_dbms:117] Failed to execute "alter system set track_wal_io_timing to 'off';" to update dbms for error: unrecognized configuration parameter "track_wal_io_timing"

[2025-04-26 00:26:15,365 ERROR] [postgres.py:update_dbms:117] Failed to execute "alter system set track_wal_io_timing to 'off';" to update dbms for error: unrecognized configuration parameter "track_wal_io_timing"

[2025-04-26 00:26:15,444 ERROR] [postgres.py:update_dbms:117] Failed to execute "alter system set autovacuum_max_workers to '0';" to update dbms for error: 0 is outside the valid range for parameter "autovacuum_max_workers" (1 .. 262143)

[2025-04-26 00:26:53,356 ERROR] [postgres.py:update_dbms:117] Failed to execute "alter system set track_wal_io_timing to 'off';" to update dbms for error: unrecognized configuration parameter "track_wal_io_timing"

[2025-04-26 00:28:18,609 ERROR] [postgres.py:update_dbms:117] Failed to execute "alter system set track_wal_io_timing to 'on';" to update dbms for error: unrecognized configuration parameter "track_wal_io_timing"

[2025-04-26 00:28:18,685 ERROR] [postgres.py:update_dbms:117] Failed to execute "alter system set autovacuum_max_workers to '0';" to update dbms for error: 0 is outside the valid range for parameter "autovacuum_max_workers" (1 .. 262143)

[2025-04-26 00:28:45,756 ERROR] [postgres.py:update_dbms:117] Failed to execute "alter system set temp_buffers to '0';" to update dbms for error: 0 8kB is outside the valid range for parameter "temp_buffers" (100 .. 1073741823)

[2025-04-26 00:28:45,764 ERROR] [postgres.py:update_dbms:117] Failed to execute "alter system set track_wal_io_timing to 'off';" to update dbms for error: unrecognized configuration parameter "track_wal_io_timing"

[2025-04-26 00:28:45,854 ERROR] [postgres.py:update_dbms:117] Failed to execute "alter system set autovacuum_max_workers to '0';" to update dbms for error: 0 is outside the valid range for parameter "autovacuum_max_workers" (1 .. 262143)

[2025-04-26 00:29:06,150 ERROR] [postgres.py:update_dbms:117] Failed to execute "alter system reset all;" to update dbms for error: 'NoneType' object has no attribute 'autocommit'
[2025-04-26 00:29:08,982 ERROR] [postgres.py:update_dbms:117] Failed to execute "alter system set track_wal_io_timing to 'off';" to update dbms for error: unrecognized configuration parameter "track_wal_io_timing"

[2025-04-26 00:29:39,047 ERROR] [postgres.py:update_dbms:117] Failed to execute "alter system set temp_buffers to '0';" to update dbms for error: 0 8kB is outside the valid range for parameter "temp_buffers" (100 .. 1073741823)

[2025-04-26 00:29:39,055 ERROR] [postgres.py:update_dbms:117] Failed to execute "alter system set track_wal_io_timing to 'on';" to update dbms for error: unrecognized configuration parameter "track_wal_io_timing"

[2025-04-26 00:29:39,139 ERROR] [postgres.py:update_dbms:117] Failed to execute "alter system set autovacuum_max_workers to '0';" to update dbms for error: 0 is outside the valid range for parameter "autovacuum_max_workers" (1 .. 262143)

[2025-04-26 00:30:13,297 ERROR] [postgres.py:update_dbms:117] Failed to execute "alter system set track_wal_io_timing to 'on';" to update dbms for error: unrecognized configuration parameter "track_wal_io_timing"

[2025-04-26 00:30:13,383 ERROR] [postgres.py:update_dbms:117] Failed to execute "alter system set autovacuum_max_workers to '0';" to update dbms for error: 0 is outside the valid range for parameter "autovacuum_max_workers" (1 .. 262143)

[2025-04-26 00:30:55,371 ERROR] [postgres.py:update_dbms:117] Failed to execute "alter system set track_wal_io_timing to 'on';" to update dbms for error: unrecognized configuration parameter "track_wal_io_timing"

[2025-04-26 00:30:55,449 ERROR] [postgres.py:update_dbms:117] Failed to execute "alter system set autovacuum_max_workers to '0';" to update dbms for error: 0 is outside the valid range for parameter "autovacuum_max_workers" (1 .. 262143)

[2025-04-26 00:31:41,824 ERROR] [postgres.py:update_dbms:117] Failed to execute "alter system set track_wal_io_timing to 'off';" to update dbms for error: unrecognized configuration parameter "track_wal_io_timing"

[2025-04-26 00:31:41,919 ERROR] [postgres.py:update_dbms:117] Failed to execute "alter system set autovacuum_max_workers to '0';" to update dbms for error: 0 is outside the valid range for parameter "autovacuum_max_workers" (1 .. 262143)

[2025-04-26 00:32:13,175 ERROR] [postgres.py:update_dbms:117] Failed to execute "alter system set track_wal_io_timing to 'off';" to update dbms for error: unrecognized configuration parameter "track_wal_io_timing"

[2025-04-26 00:32:56,427 ERROR] [postgres.py:update_dbms:117] Failed to execute "alter system set track_wal_io_timing to 'on';" to update dbms for error: unrecognized configuration parameter "track_wal_io_timing"

[2025-04-26 00:32:56,507 ERROR] [postgres.py:update_dbms:117] Failed to execute "alter system set autovacuum_max_workers to '0';" to update dbms for error: 0 is outside the valid range for parameter "autovacuum_max_workers" (1 .. 262143)

[2025-04-26 00:33:25,661 ERROR] [postgres.py:update_dbms:117] Failed to execute "alter system set track_wal_io_timing to 'on';" to update dbms for error: unrecognized configuration parameter "track_wal_io_timing"

[2025-04-26 00:34:04,852 ERROR] [postgres.py:update_dbms:117] Failed to execute "alter system set track_wal_io_timing to 'off';" to update dbms for error: unrecognized configuration parameter "track_wal_io_timing"

[2025-04-26 00:34:04,934 ERROR] [postgres.py:update_dbms:117] Failed to execute "alter system set autovacuum_max_workers to '0';" to update dbms for error: 0 is outside the valid range for parameter "autovacuum_max_workers" (1 .. 262143)

[2025-04-26 00:34:35,343 ERROR] [postgres.py:update_dbms:117] Failed to execute "alter system set track_wal_io_timing to 'off';" to update dbms for error: unrecognized configuration parameter "track_wal_io_timing"

